<?xml version="1.0" encoding="utf-8"?>
<!-- This URDF was automatically created by SolidWorks to URDF Exporter! Originally created by
Stephen Brawner (brawner@gmail.com) 
     Commit Version: 1.6.0-4-g7f85cfe  Build Version: 1.6.7995.38578
     For more information, please see http://wiki.ros.org/sw_urdf_exporter -->
<robot xmlns:xacro="http://www.ros.org/wiki/xacro" name="line_follow_robot_description">
    <!-- 0.082 -->

    <link name="base_link">
    </link>

    <joint name="base_link_to_chassis" type="fixed">
        <origin xyz="0.0 0.0 0.082" rpy="0.0 0.0 0.0" />
        <parent link="base_link" />
        <child link="chassis" />
    </joint>

    <link
        name="chassis">
        <inertial>
            <origin
                xyz="-0.0189338714262096 0.00069316353741691 0.00627681186620915"
                rpy="0 0 0" />
            <mass
                value="0.96" />
            <inertia
                ixx="0.0021060110693492"
                ixy="1.76769326367521E-06"
                ixz="-4.58025918247966E-07"
                iyy="0.00181575190997712"
                iyz="5.94003631824428E-07"
                izz="0.00373273729223352" />
        </inertial>
        <visual>
            <origin
                xyz="0 0 0"
                rpy="0 0 0" />
            <geometry>
                <mesh
                    filename="package://line_follow_robot_description/meshes/chassis.STL" />
            </geometry>
            <material
                name="">
                <color
                    rgba="0.792156862745098 0.819607843137255 0.933333333333333 1" />
            </material>
        </visual>
        <collision>
            <origin
                xyz="0 0 0"
                rpy="0 0 0" />
            <geometry>
                <mesh
                    filename="package://line_follow_robot_description/meshes/chassis.STL" />
            </geometry>
        </collision>
    </link>

    <xacro:robot_wheel wheel_prefix="left_front" />
    <xacro:robot_wheel wheel_prefix="left_rear" />
    <xacro:robot_wheel wheel_prefix="right_front" />
    <xacro:robot_wheel wheel_prefix="right_rear" />

    <link
        name="lidar">
        <inertial>
            <origin
                xyz="-0.0195048948992104 0.0362156974703284 0.0350383093115848"
                rpy="0 0 0" />
            <mass
                value="0.143" />
            <inertia
                ixx="7.34746440088868E-05"
                ixy="0"
                ixz="0"
                iyy="4.62767161181516E-05"
                iyz="0"
                izz="0.000107960183716792" />
        </inertial>
        <visual>
            <origin
                xyz="0 0 0"
                rpy="0 0 0" />
            <geometry>
                <mesh
                    filename="package://line_follow_robot_description/meshes/lidar.STL" />
            </geometry>
            <material
                name="">
                <color
                    rgba="0.1 0.1 0.1 1" />
            </material>
        </visual>
        <collision>
            <origin
                xyz="0 0 0"
                rpy="0 0 0" />
            <geometry>
                <mesh
                    filename="package://line_follow_robot_description/meshes/lidar.STL" />
            </geometry>
        </collision>
    </link>
    <joint
        name="lidar_connect_joint"
        type="fixed">
        <origin
            xyz="0.080027 -0.041966 0.055"
            rpy="0 0 0" />
        <parent
            link="chassis" />
        <child
            link="lidar" />
        <axis
            xyz="0 0 0" />
    </joint>
    <link
        name="camera">
        <inertial>
            <origin
                xyz="-0.00269952282557905 -0.0201858207235722 6.93889390390723E-18"
                rpy="0 0 0" />
            <mass
                value="0.004" />
            <inertia
                ixx="8.41847786919127E-07"
                ixy="-9.98650670123063E-08"
                ixz="0"
                iyy="4.65403328847223E-07"
                iyz="0"
                izz="4.97218440111319E-07" />
        </inertial>
        <visual>
            <origin
                xyz="0 0 0"
                rpy="0 0 0" />
            <geometry>
                <mesh
                    filename="package://line_follow_robot_description/meshes/camera.STL" />
            </geometry>
            <material
                name="">
                <color
                    rgba="0.79 0.825 0.94 1" />
            </material>
        </visual>
        <collision>
            <origin
                xyz="0 0 0"
                rpy="0 0 0" />
            <geometry>
                <mesh
                    filename="package://line_follow_robot_description/meshes/camera.STL" />
            </geometry>
        </collision>
    </link>
    <joint
        name="camera_joint"
        type="revolute">
        <origin
            xyz="0.12353 3.4296E-05 0.0565"
            rpy="1.5708 0 0" />
        <parent
            link="chassis" />
        <child
            link="camera" />
        <axis
            xyz="0 0 1" />
        <limit
            lower="${camera_joint_lower_limit}"
            upper="${camera_joint_upper_limit}"
            effort="0"
            velocity="0" />
    </joint>
</robot>